Workbook
Name kythuat: #REF!
Name nhaplieu: #REF!
Name nhaplieuPLHD: #REF!
Name NoidungPLHD: #REF!
Name PLHD: #REF!
Name Thongsothang: #REF!
Name ThongtinHD: #REF!
Name ThongtinPLHD: #REF!

Sheet Contract data
A1: contract date | B1: contract_ID | C1: project_address | D1: province_old | E1: province_new | F1: customer_ID | G1: contract_duration | H1: project_ID | I1: saleman_ID | J1: warranty_period_months | K1: maintenance_period_months | L1: contract_source | M1: elevator_brand | N1: product_ID | O1: shaft_type | P1: elevator_type | Q1: elevator_traction_machine | R1: control_system | S1: contract_value_before_tax | T1: contract_vat_amount | U1: contract_value_after_tax | V1: net_price | W1: discount | X1: customer_commission | Y1: sales_commission | Z1: import_date | AA1: import_staff
A2: 45500 | B2: 1001/HĐ-2024 | C2: thửa 330, tbđ số 1, p. thạnh mỹ lợi, tp. thủ đức, tp. hcm | D2: TP Hồ Chí Minh | E2: =VLOOKUP(D2,'shipping inf'!B:D,2,FALSE) -> TP Hồ Chí Minh | F2: KH001 | G2: 120 | H2: 2411000101 | I2: D2007 | J2: 24 | K2: 24 | L2: MKT Cơ bản | M2: Sanyo Minh Long | N2: =VLOOKUP(Table1[[#This Row],[elevator_traction_machine]],'Product inf'!A:B,2,FALSE) -> SP015 | O2: Bê tông | P2: Tải khách | Q2: Ziehl-Abegg - Đức | R2: Sanotec DREAM control | S2: 415000000 | U2: 415000000 | V2: 476800000 | Y2: 7000000 | Z2: 45500 | AA2: D200772024
A3: 45306 | B3: 101/HĐ-2024 | C3: căn hộ t21-1 vinhomes grand park, p. long thạnh mỹ, tp. thủ đức, tphcm | D3: TP Hồ Chí Minh | E3: =VLOOKUP(D3,'shipping inf'!B:D,2,FALSE) -> TP Hồ Chí Minh | F3: KH002 | G3: 75 | H3: 2410100101 | I3: D3001 | J3: 24 | K3: 24 | L3: Ban Giám Đốc | M3: Sanyo Minh Long | N3: =VLOOKUP(Table1[[#This Row],[elevator_traction_machine]],'Product inf'!A:B,2,FALSE) -> SP006 | O3: Kết cấu thép | P3: Tải khách | Q3: Sanotec - Nhật Bản | R3: Sanotec DREAM control | S3: 440000000 | U3: 440000000 | Y3: 7557500 | Z3: 45309 | AA3: D300112024
A4: 45671 | B4: 101/HĐ-2025 | C4: thửa 407-408 bình thới, p.14, q.11, tphcm | D4: TP Hồ Chí Minh | E4: =VLOOKUP(D4,'shipping inf'!B:D,2,FALSE) -> TP Hồ Chí Minh | F4: KH003 | G4: 90 | H4: 2510100101 | I4: D3001 | J4: 24 | K4: 12 | L4: Ban Giám Đốc | M4: Sanyo Minh Long | N4: =VLOOKUP(Table1[[#This Row],[elevator_traction_machine]],'Product inf'!A:B,2,FALSE) -> SP006 | O4: Bê tông | P4: Tải khách | Q4: Sanotec - Nhật Bản | R4: Sanotec DREAM control | S4: 372000000 | U4: 372000000 | V4: 367000000 | Y4: 5220000 | Z4: 45671 | AA4: D300112025
A5: 46079 | B5: 101A.ĐL/HĐ-2026 | C5: 366 phan đình phùng, phường xuân hương - đà lạt, lâm đồng | D5: Lâm Đồng | E5: =VLOOKUP(D5,'shipping inf'!B:D,2,FALSE) -> Lâm Đồng | F5: KH004 | G5: 90 | H5: 2610100101 | I5: D3002 | J5: 24 | K5: 24 | L5: Ban Giám Đốc | M5: Sanyo Minh Long | N5: =VLOOKUP(Table1[[#This Row],[elevator_traction_machine]],'Product inf'!A:B,2,FALSE) -> SP006 | O5: Kết cấu thép | P5: Tải khách | Q5: Sanotec - Nhật Bản | R5: Sanotec DREAM control | S5: 400000000 | U5: 400000000 | V5: 400000000 | Z5: 46087 | AA5: D300222026
A6: 45320 | B6: 102/HĐ-2024 | C6: lô p-3, đường số 7, kcn long hậu mở rộng, x. long hậu, h. cần giuộc, long an (fp1) | D6: TP Hồ Chí Minh | E6: =VLOOKUP(D6,'shipping inf'!B:D,2,FALSE) -> TP Hồ Chí Minh | F6: KH005 | G6: 60 | H6: 2410100201 | I6: D3001 | J6: 24 | K6: 12 | L6: Ban Giám Đốc | M6: Sanyo Minh Long | N6: =VLOOKUP(Table1[[#This Row],[elevator_traction_machine]],'Product inf'!A:B,2,FALSE) -> SP006 | O6: Kết cấu thép | P6: Tải khách | Q6: Sanotec - Nhật Bản | R6: Sanotec DREAM control | S6: 1039200000 | T6: 41568000 | U6: 1080768000 | Y6: 12392000 | Z6: 45329 | AA6: D300112024
A7: 45714 | B7: 102/HĐ-2025 | C7: xã trung an, h. củ chi, tphcm | D7: TP Hồ Chí Minh | E7: =VLOOKUP(D7,'shipping inf'!B:D,2,FALSE) -> TP Hồ Chí Minh | F7: KH006 | G7: 150 | H7: 2510100201 | I7: D3001 | J7: 24 | K7: 12 | L7: Ban Giám Đốc | M7: Sanyo Minh Long | N7: =VLOOKUP(Table1[[#This Row],[elevator_traction_machine]],'Product inf'!A:B,2,FALSE) -> SP006 | O7: Bê tông | P7: Tải khách | Q7: Sanotec - Nhật Bản | R7: Sanotec DREAM control | S7: 390000000 | U7: 390000000 | V7: 373000000 | X7: 0 | Y7: 5400000 | Z7: 45726 | AA7: D300122025
A8: 46058 | B8: 102/HĐ-2026 | C8: thửa đất số 06, tbđ 81, p.tân mỹ, tphcm | D8: TP Hồ Chí Minh | E8: =VLOOKUP(D8,'shipping inf'!B:D,2,FALSE) -> TP Hồ Chí Minh | F8: KH007 | G8: 90 | H8: 2610100201 | I8: D3001 | J8: 24 | K8: 24 | L8: Ban Giám Đốc | M8: Sanyo Minh Long | N8: =VLOOKUP(Table1[[#This Row],[elevator_traction_machine]],'Product inf'!A:B,2,FALSE) -> SP006 | O8: Bê tông | P8: Tải khách | Q8: Sanotec - Nhật Bản | R8: Sanotec DREAM control | S8: 557000000 | U8: 557000000 | V8: 556000000 | Z8: 46059 | AA8: D300122026
A9: 45353 | B9: 103/HĐ-2024 | C9: số 12 đường số 10, kp3, p. bình thuận, q.7, tp. hcm | D9: TP Hồ Chí Minh | E9: =VLOOKUP(D9,'shipping inf'!B:D,2,FALSE) -> TP Hồ Chí Minh | F9: KH008 | G9: 70 | H9: 2410100301 | I9: D3001 | J9: 24 | K9: 12 | L9: Ban Giám Đốc | M9: Sanyo Minh Long | N9: =VLOOKUP(Table1[[#This Row],[elevator_traction_machine]],'Product inf'!A:B,2,FALSE) -> SP015 | O9: Bê tông | P9: Tải khách | Q9: Ziehl-Abegg - Đức | R9: Sanotec DREAM control | S9: 454000000 | T9: 20000000 | U9: 474000000 | Y9: 5540000 | Z9: 45360 | AA9: D300132024
A10: 45419 | B10: 104/HĐ-2024 | C10: 314 nguyễn thái sơn, p.4, q. gò vấp, tp. hcm | D10: TP Hồ Chí Minh | E10: =VLOOKUP(D10,'shipping inf'!B:D,2,FALSE) -> TP Hồ Chí Minh | F10: KH009 | G10: 120 | H10: 2410100401 | I10: D3001 | J10: 24 | K10: 12 | L10: Ban Giám Đốc | M10: Sanyo Minh Long | N10: =VLOOKUP(Table1[[#This Row],[elevator_traction_machine]],'Product inf'!A:B,2,FALSE) -> SP015 | O10: Bê tông | P10: Tải khách | Q10: Ziehl-Abegg - Đức | R10: Sanotec DREAM control | S10: 425000000 | U10: 425000000 | X10: 3000000 | Y10: 5250000 | Z10: 45420 | AA10: D300152024
A11: 45721 | B11: 104/HĐ-2025 | C11: 301/16/10 vườn lài, p. an phú đông, q.12, tphcm | D11: TP Hồ Chí Minh | E11: =VLOOKUP(D11,'shipping inf'!B:D,2,FALSE) -> TP Hồ Chí Minh | F11: KH010 | G11: 120 | H11: 2510100401 | I11: D3001 | J11: 24 | K11: 24 | L11: Ban Giám Đốc | M11: Sanyo Minh Long | N11: =VLOOKUP(Table1[[#This Row],[elevator_traction_machine]],'Product inf'!A:B,2,FALSE) -> SP015 | O11: Bê tông | P11: Tải khách | Q11: Ziehl-Abegg - Đức | R11: Sanotec CEN control | S11: 355000000 | U11: 355000000 | V11: 350000000 | X11: 0 | Y11: 5050000 | Z11: 45724 | AA11: D300132025
A12: 46055 | B12: 104/HĐ-2026 | C12: kdc thửa 408, tờ 58/bđđc, p.bình thạnh, tphcm | D12: TP Hồ Chí Minh | E12: =VLOOKUP(D12,'shipping inf'!B:D,2,FALSE) -> TP Hồ Chí Minh | F12: KH011 | G12: 90 | H12: 2610100401 | I12: D3001 | J12: 24 | K12: 24 | L12: Ban Giám Đốc | M12: Sanyo Minh Long | N12: =VLOOKUP(Table1[[#This Row],[elevator_traction_machine]],'Product inf'!A:B,2,FALSE) -> SP006 | O12: Bê tông | P12: Tải khách | Q12: Sanotec - Nhật Bản | R12: Sanotec DREAM control | S12: 800000000 | U12: 800000000 | V12: 800000000 | Z12: 46059 | AA12: D300122026
A13: 46055 | B13: 104/HĐ-2026 | C13: kdc thửa 408, tờ 58/bđđc, p.bình thạnh, tphcm | D13: TP Hồ Chí Minh | E13: =VLOOKUP(D13,'shipping inf'!B:D,2,FALSE) -> TP Hồ Chí Minh | F13: KH011 | G13: 90 | H13: 2610100402 | I13: D3001 | J13: 24 | K13: 24 | L13: Ban Giám Đốc | M13: Sanyo Minh Long | N13: =VLOOKUP(Table1[[#This Row],[elevator_traction_machine]],'Product inf'!A:B,2,FALSE) -> SP006 | O13: Bê tông | P13: Tải khách | Q13: Sanotec - Nhật Bản | R13: Sanotec DREAM control | S13: 800000000 | U13: 800000000 | V13: 800000000 | Z13: 46059 | AA13: D300122026
A14: 45311 | B14: 105/HĐ-2024 | C14: số 60 lê tự tài, p.4, q. phú nhuận, tp. hcm | D14: TP Hồ Chí Minh | E14: =VLOOKUP(D14,'shipping inf'!B:D,2,FALSE) -> TP Hồ Chí Minh | F14: KH011 | G14: 90 | H14: 2410100501 | I14: D3001 | J14: 24 | K14: 12 | L14: Ban Giám Đốc | M14: Sanyo Minh Long | N14: =VLOOKUP(Table1[[#This Row],[elevator_traction_machine]],'Product inf'!A:B,2,FALSE) -> SP006 | O14: Bê tông | P14: Tải khách | Q14: Sanotec - Nhật Bản | R14: Sanotec DREAM control | S14: 380000000 | U14: 380000000 | X14: 3000000 | Y14: 4800000 | Z14: 45311 | AA14: D300112024
A15: 45776 | B15: 105/HĐ-2025 | C15: tòa nhà hội nghị - khối lâu đài lachateau pl1 | D15: TP Hồ Chí Minh | E15: =VLOOKUP(D15,'shipping inf'!B:D,2,FALSE) -> TP Hồ Chí Minh | F15: KH012 | G15: 90 | H15: 2510100502 | I15: D3001 | J15: 24 | K15: 24 | L15: Ban Giám Đốc | M15: Sanyo Minh Long | N15: =VLOOKUP(Table1[[#This Row],[elevator_traction_machine]],'Product inf'!A:B,2,FALSE) -> SP006 | O15: Bê tông | P15: Tải khách | Q15: Sanotec - Nhật Bản | R15: Sanotec DREAM control | S15: 865000000 | T15: 69200000 | U15: 934200000 | V15: 896404000 | Y15: 11050000 | Z15: 45776 | AA15: D300142025
A16: 45776 | B16: 105/HĐ-2025 | C16: tòa nhà hội nghị - khối lâu đài lachateau pl2 | D16: TP Hồ Chí Minh | E16: =VLOOKUP(D16,'shipping inf'!B:D,2,FALSE) -> TP Hồ Chí Minh | F16: KH012 | G16: 90 | H16: 2510100502 | I16: D3001 | J16: 24 | K16: 24 | L16: Ban Giám Đốc | M16: Sanyo Minh Long | N16: =VLOOKUP(Table1[[#This Row],[elevator_traction_machine]],'Product inf'!A:B,2,FALSE) -> SP006 | O16: Bê tông | P16: Tải khách | Q16: Sanotec - Nhật Bản | R16: Sanotec DREAM control | U16: 0 | Z16: 45776 | AA16: D300142025
A17: 46062 | B17: 105/HĐ-2026 | C17: số 29 đường tân canh, p.tân sơn hòa, tphcm | D17: TP Hồ Chí Minh | E17: =VLOOKUP(D17,'shipping inf'!B:D,2,FALSE) -> TP Hồ Chí Minh | F17: KH013 | G17: 90 | H17: 2610100501 | I17: D3001 | J17: 24 | K17: 24 | L17: Ban Giám Đốc | M17: Sanyo Minh Long | N17: =VLOOKUP(Table1[[#This Row],[elevator_traction_machine]],'Product inf'!A:B,2,FALSE) -> SP010 | O17: Kết cấu thép | P17: Tải khách | Q17: Sanotec Eco - Trung Quốc | R17: Sanotec Eco control | S17: 744250000 | U17: 744250000 | V17: 707500000 | Z17: 46062 | AA17: D300122026
A18: 45358 | B18: 106/HĐ-2024 | C18: ấp 3, x. phước kiển, h. nhà bè, tp. hcm (thửa đất số 117, tbđ số 6 ) | D18: TP Hồ Chí Minh | E18: =VLOOKUP(D18,'shipping inf'!B:D,2,FALSE) -> TP Hồ Chí Minh | F18: KH014 | G18: 90 | H18: 2410100601 | I18: D3001 | J18: 24 | K18: 12 | L18: Ban Giám Đốc | M18: Sanyo Minh Long | N18: =VLOOKUP(Table1[[#This Row],[elevator_traction_machine]],'Product inf'!A:B,2,FALSE) -> SP009 | O18: Kết cấu thép | P18: Tải khách | Q18: Sanotec Eco - Nhật Bản | R18: Sanotec DREAM control | S18: 325000000 | T18: 26000000 | U18: 351000000 | Y18: 4250000 | Z18: 45358 | AA18: D300132024
A19: 45724 | B19: 106/HĐ-2025 | C19: 541 đường nguyễn huệ, khóm 1, p.1, tp. sa đéc, đồng tháp | D19: Đồng Tháp | E19: =VLOOKUP(D19,'shipping inf'!B:D,2,FALSE) -> Đồng Tháp | F19: KH015 | G19: 90 | H19: 2510100601 | I19: D3001 | J19: 24 | K19: 12 | L19: Ban Giám Đốc | M19: Sanyo Minh Long | N19: =VLOOKUP(Table1[[#This Row],[elevator_traction_machine]],'Product inf'!A:B,2,FALSE) -> SP010 | O19: Bê tông | P19: Tải khách | Q19: Sanotec Eco - Trung Quốc | R19: Sanotec Eco control | S19: 447000000 | T19: 35760000 | U19: 482760000 | V19: 490500000 | Y19: 5670000 | Z19: 45734 | AA19: D300132025
A20: 46064 | B20: 106/HĐ-2026 | C20: 363/2/17 bình lợi, p.bình lợi trung, tphcm | D20: TP Hồ Chí Minh | E20: =VLOOKUP(D20,'shipping inf'!B:D,2,FALSE) -> TP Hồ Chí Minh | F20: KH016 | G20: 90 | H20: 2610100601 | I20: D3001 | J20: 24 | K20: 24 | L20: Ban Giám Đốc | M20: Sanyo Minh Long | N20: =VLOOKUP(Table1[[#This Row],[elevator_traction_machine]],'Product inf'!A:B,2,FALSE) -> SP006 | O20: Bê tông | P20: Tải khách | Q20: Sanotec - Nhật Bản | R20: Sanotec DREAM control | S20: 370000000 | U20: 370000000 | V20: 355500000 | X20: 6000000 | Z20: 46065 | AA20: D300122026
A21: 45365 | B21: 107/HĐ-2024 | C21: số 35 đường số 7, p. bình trưng đông. q.2, tp. hcm | D21: TP Hồ Chí Minh | E21: =VLOOKUP(D21,'shipping inf'!B:D,2,FALSE) -> TP Hồ Chí Minh | F21: KH017 | G21: 60 | H21: 2410100701 | I21: D3001 | J21: 24 | K21: 12 | L21: Ban Giám Đốc | M21: Sanyo Minh Long | N21: =VLOOKUP(Table1[[#This Row],[elevator_traction_machine]],'Product inf'!A:B,2,FALSE) -> SP006 | O21: Bê tông | P21: Tải khách | Q21: Sanotec - Nhật Bản | R21: Sanotec DREAM control | S21: 410000000 | U21: 410000000 | Y21: 5100000 | Z21: 45367 | AA21: D300132024
A22: 45721 | B22: 107/HĐ-2025 | C22: kdc cityland park hills, số 18 phan văn trị, p.10, q. gò vấp, tphcm | D22: TP Hồ Chí Minh | E22: =VLOOKUP(D22,'shipping inf'!B:D,2,FALSE) -> TP Hồ Chí Minh | F22: KH018 | G22: 90 | H22: 2510100701 | I22: D3001 | J22: 24 | K22: 12 | L22: Ban Giám Đốc | M22: Sanyo Minh Long | N22: =VLOOKUP(Table1[[#This Row],[elevator_traction_machine]],'Product inf'!A:B,2,FALSE) -> SP006 | O22: Bê tông | P22: Tải khách | Q22: Sanotec - Nhật Bản | R22: Sanotec DREAM control | S22: 400000000 | U22: 400000000 | V22: 386000000 | X22: 15000000 | Y22: 5500000 | Z22: 45722 | AA22: D300132025
A23: 46085 | B23: 107/HĐ-2026 | C23: số 18, đường b2, phường an khánh, tphcm | D23: TP Hồ Chí Minh | E23: =VLOOKUP(D23,'shipping inf'!B:D,2,FALSE) -> TP Hồ Chí Minh | F23: KH019 | G23: 50 | H23: 2610100701 | I23: D3001 | J23: 24 | K23: 24 | L23: Ban Giám Đốc | M23: Sanyo Minh Long | N23: =VLOOKUP(Table1[[#This Row],[elevator_traction_machine]],'Product inf'!A:B,2,FALSE) -> SP006 | O23: Kết cấu thép | P23: Tải khách | Q23: Sanotec - Nhật Bản | R23: Sanotec DREAM control | S23: 455000000 | T23: 36400000 | U23: 491400000 | V23: 441100000 | Z23: 46086 | AA23: D300132026
A24: 45369 | B24: 108/HĐ-2024 | C24: số 21 đường nguyễn tri phương, p. chánh nghĩa, tp. thủ dầu 1, bình dương | D24: Bình Dương | E24: =VLOOKUP(D24,'shipping inf'!B:D,2,FALSE) -> TP Hồ Chí Minh | F24: KH020 | G24: 60 | H24: 2410100801 | I24: D3001 | J24: 24 | K24: 12 | L24: Ban Giám Đốc | M24: Sanyo Minh Long | N24: =VLOOKUP(Table1[[#This Row],[elevator_traction_machine]],'Product inf'!A:B,2,FALSE) -> SP009 | O24: Bê tông | P24: Tải khách | Q24: Sanotec Eco - Nhật Bản | R24: Sanotec DREAM control | S24: 357500000 | U24: 357500000 | Y24: 4575000 | Z24: 45371 | AA24: D300132024
A25: 45793 | B25: 108/HĐ-2025 | C25: số 66m, võ văn kiệt, phường 9, tp vĩnh long, tỉnh vĩnh long | D25: Vĩnh Long | E25: =VLOOKUP(D25,'shipping inf'!B:D,2,FALSE) -> Vĩnh Long | F25: KH021 | G25: 90 | H25: 2510100801 | I25: D3001 | J25: 24 | K25: 12 | L25: Ban Giám Đốc | M25: Sanyo Minh Long | N25: =VLOOKUP(Table1[[#This Row],[elevator_traction_machine]],'Product inf'!A:B,2,FALSE) -> SP015 | O25: Bê tông | P25: Tải khách | Q25: Ziehl-Abegg - Đức | R25: Sanotec DREAM control | S25: 3.7037037e+08 | T25: 29629630 | U25: 4e+08 | V25: 393000000 | Y25: 4903704 | Z25: 45794 | AA25: D300152025
A26: 46088 | B26: 108/HĐ-2026 | C26: 27/19 huỳnh tịnh của, p.xuân hòa, tphcm | D26: TP Hồ Chí Minh | E26: =VLOOKUP(D26,'shipping inf'!B:D,2,FALSE) -> TP Hồ Chí Minh | F26: KH022 | G26: 60 | H26: 2610100801 | I26: D3001 | J26: 24 | K26: 24 | L26: Ban Giám Đốc | M26: Sanyo Minh Long | N26: =VLOOKUP(Table1[[#This Row],[elevator_traction_machine]],'Product inf'!A:B,2,FALSE) -> SP006 | O26: Kết cấu thép | P26: Tải khách | Q26: Sanotec - Nhật Bản | R26: Sanotec DREAM control | S26: 459000000 | U26: 459000000 | V26: 457000000 | Z26: 46090 | AA26: D300132026
A27: 45408 | B27: 109/HĐ-2024 | C27: 31/30/6 lê lai, p.3, q. gò vấp, tp. hcm (p1) | D27: TP Hồ Chí Minh | E27: =VLOOKUP(D27,'shipping inf'!B:D,2,FALSE) -> TP Hồ Chí Minh | F27: KH023 | G27: 60 | H27: 2410100901 | I27: D3001 | J27: 24 | K27: 12 | L27: Ban Giám Đốc | M27: Sanyo Minh Long | N27: =VLOOKUP(Table1[[#This Row],[elevator_traction_machine]],'Product inf'!A:B,2,FALSE) -> SP003 | O27: Bê tông | P27: Tải khách | Q27: Fuji Korea - Hàn Quốc | R27: Sanotec DREAM control | S27: 305000000 | U27: 305000000 | X27: 5000000 | Y27: 7100000 | Z27: 45418 | AA27: D300142024
A28: 45408 | B28: 109/HĐ-2024 | C28: 31/30/8 lê lai, p.3, q. gò vấp, tp. hcm (p2) | D28: TP Hồ Chí Minh | E28: =VLOOKUP(D28,'shipping inf'!B:D,2,FALSE) -> TP Hồ Chí Minh | F28: KH023 | G28: 60 | H28: 2410100902 | I28: D3001 | J28: 24 | K28: 12 | L28: Ban Giám Đốc | M28: Sanyo Minh Long | N28: =VLOOKUP(Table1[[#This Row],[elevator_traction_machine]],'Product inf'!A:B,2,FALSE) -> SP003 | O28: Bê tông | P28: Tải khách | Q28: Fuji Korea - Hàn Quốc | R28: Sanotec DREAM control | S28: 305000000 | U28: 305000000 | Z28: 45418 | AA28: D300142024
A29: 45734 | B29: 109/HĐ-2025 | C29: nhà số 6, ngõ 658 trương định, tổ 8, p. giáp bát, q. hoàng mai, hà nội | D29: Hà Nội | E29: =VLOOKUP(D29,'shipping inf'!B:D,2,FALSE) -> Hà Nội | F29: KH024 | G29: 90 | H29: 2510100901 | I29: D3001 | J29: 24 | K29: 12 | L29: Ban Giám Đốc | M29: Sanyo Minh Long | N29: =VLOOKUP(Table1[[#This Row],[elevator_traction_machine]],'Product inf'!A:B,2,FALSE) -> SP011 | O29: Bê tông | P29: Tải khách | Q29: Sanotec HP - Trung Quốc | R29: Sanotec Thuỷ lực control | S29: 330000000 | U29: 330000000 | V29: 245000000 | Y29: 4800000 | Z29: 45736 | AA29: D300132025
A30: 46100 | B30: 109/HĐ-2026 | C30: số 5 hẻm 9 đường số 66, phường an khánh, tphcm | D30: TP Hồ Chí Minh | E30: =VLOOKUP(D30,'shipping inf'!B:D,2,FALSE) -> TP Hồ Chí Minh | F30: KH025 | G30: 60 | H30: 2610100901 | I30: D3001 | J30: 24 | K30: 24 | L30: Ban Giám Đốc | M30: Sanyo Minh Long | N30: =VLOOKUP(Table1[[#This Row],[elevator_traction_machine]],'Product inf'!A:B,2,FALSE) -> SP015 | O30: Bê tông | P30: Tải khách | Q30: Ziehl-Abegg - Đức | R30: Sanotec DREAM control | S30: 407000000 | T30: 32560000 | U30: 439560000 | V30: 383000000 | Z30: 46100 | AA30: D300132026
A31: 45406 | B31: 110/HĐ-2024 | C31: nhà số 42, đường phạm ngọc thạch, p.9. tp. vũng tàu, bà rịa - vũng tàu | D31: Bà Rịa – Vũng Tàu | E31: =VLOOKUP(D31,'shipping inf'!B:D,2,FALSE) -> TP Hồ Chí Minh | F31: KH026 | G31: 60 | H31: 2410101001 | I31: D3001 | J31: 24 | K31: 12 | L31: Ban Giám Đốc | M31: Sanyo Minh Long | N31: =VLOOKUP(Table1[[#This Row],[elevator_traction_machine]],'Product inf'!A:B,2,FALSE) -> SP009 | O31: Kết cấu thép | P31: Tải khách | Q31: Sanotec Eco - Nhật Bản | R31: Sanotec DREAM control | S31: 390000000 | U31: 390000000 | Y31: 4900000 | Z31: 45414 | AA31: D300142024
A32: 45762 | B32: 110/HĐ-2025 | C32: 113/79/1 trần văn đang, phường 11, quận 3, tphcm | D32: TP Hồ Chí Minh | E32: =VLOOKUP(D32,'shipping inf'!B:D,2,FALSE) -> TP Hồ Chí Minh | F32: KH027 | G32: 180 | H32: 2510101001 | I32: D3001 | J32: 24 | K32: 24 | L32: MKT Đối tác | M32: Sanyo Minh Long | N32: =VLOOKUP(Table1[[#This Row],[elevator_traction_machine]],'Product inf'!A:B,2,FALSE) -> SP006 | O32: Bê tông | P32: Tải khách | Q32: Sanotec - Nhật Bản | R32: Sanotec DREAM control | S32: 372000000 | U32: 372000000 | V32: 391000000 | X32: 25000000 | Y32: 4920000 | Z32: 45762 | AA32: D300142025
A33: 46099 | B33: 110/HĐ-2026 | C33: lô sth 23-02 đường số 3, kdt mới lê hồng phong ii, p.nam nha trang, khánh hòa | D33: Khánh Hòa | E33: =VLOOKUP(D33,'shipping inf'!B:D,2,FALSE) -> Khánh Hòa | F33: KH028 | G33: 75 | H33: 2610101001 | I33: D3001 | J33: 24 | K33: 24 | L33: Ban Giám Đốc | M33: Sanyo Minh Long | N33: =VLOOKUP(Table1[[#This Row],[elevator_traction_machine]],'Product inf'!A:B,2,FALSE) -> SP005 | O33: Bê tông | P33: Tải khách | Q33: Sanotec - Eco Trung Quốc | R33: Sanotec Eco control | S33: 335000000 | U33: 335000000 | V33: 335000000 | Z33: 46100 | AA33: D300132026
A34: 45294 | B34: 1101/HĐ-2024 | C34: 88 đường b13 nguyễn hữu thọ, phước kiển, nhơn đức, nhà bè, tp. hcm | D34: TP Hồ Chí Minh | E34: =VLOOKUP(D34,'shipping inf'!B:D,2,FALSE) -> TP Hồ Chí Minh | F34: KH029 | G34: 60 | H34: 2411100101 | I34: D2001 | J34: 24 | K34: 24 | L34: MKT Cơ bản | M34: Sanyo Minh Long | N34: =VLOOKUP(Table1[[#This Row],[elevator_traction_machine]],'Product inf'!A:B,2,FALSE) -> SP015 | O34: Bê tông | P34: Tải khách | Q34: Ziehl-Abegg - Đức | R34: Sanotec DREAM control | S34: 373000000 | U34: 373000000 | V34: 381500000 | X34: 12000000 | Y34: 6000000 | Z34: 45295 | AA34: D200112024
A35: 45715 | B35: 1101/HĐ-2025 | C35: 815 lạc long quân, p.10, q. tân bình, tphcm | D35: TP Hồ Chí Minh | E35: =VLOOKUP(D35,'shipping inf'!B:D,2,FALSE) -> TP Hồ Chí Minh | F35: KH030 | G35: 180 | H35: 2511100101 | I35: D2001 | J35: 24 | K35: 36 | L35: Sales MQH cá nhân | M35: Sanyo Minh Long | N35: =VLOOKUP(Table1[[#This Row],[elevator_traction_machine]],'Product inf'!A:B,2,FALSE) -> SP015 | O35: Bê tông | P35: Tải khách | Q35: Ziehl-Abegg - Đức | R35: Sanotec DREAM control | S35: 436000000 | U35: 436000000 | V35: 445510000 | X35: 0 | Y35: 6000000 | Z35: 45716 | AA35: D200122025
A36: 45358 | B36: 1102/HĐ-2024 | C36: đội 3, thôn phan xá, x. xuân thủy, h. lệ thủy, quảng bình | D36: Quảng Bình | E36: =VLOOKUP(D36,'shipping inf'!B:D,2,FALSE) -> Quảng Trị | F36: KH031 | G36: 90 | H36: 2411100201 | I36: D2001 | J36: 24 | K36: 12 | L36: Sales MQH cá nhân | M36: Sanyo Minh Long | N36: =VLOOKUP(Table1[[#This Row],[elevator_traction_machine]],'Product inf'!A:B,2,FALSE) -> SP009 | O36: Bê tông | P36: Tải khách | Q36: Sanotec Eco - Nhật Bản | R36: Sanotec DREAM control | S36: 323400000 | U36: 323400000 | Y36: 6000000 | Z36: 45372 | AA36: D200132024
A37: 45761 | B37: 1102/HĐ-2025 | C37: 189 nguyễn trọng tuyển, phường 8, quận phú nhuận, tphcm | D37: TP Hồ Chí Minh | E37: =VLOOKUP(D37,'shipping inf'!B:D,2,FALSE) -> TP Hồ Chí Minh | F37: KH032 | G37: 540 | H37: 2511100201 | I37: D2001 | J37: 24 | K37: 24 | L37: MKT Đối tác | M37: Sanyo Minh Long | N37: =VLOOKUP(Table1[[#This Row],[elevator_traction_machine]],'Product inf'!A:B,2,FALSE) -> SP015 | O37: Bê tông | P37: Tải khách | Q37: Ziehl-Abegg - Đức | R37: Sanotec DREAM control | S37: 456000000 | U37: 456000000 | V37: 475000000 | X37: 25000000 | Y37: 6000000 | Z37: 45761 | AA37: D200142025
A38: 45390 | B38: 1103/HĐ-2024 | C38: lô 50, 51 ktđc ngô gia khảm, p. trà bá, tp. plei ku, gia lai | D38: Gia Lai | E38: =VLOOKUP(D38,'shipping inf'!B:D,2,FALSE) -> Gia Lai | F38: KH033 | G38: 60 | H38: 2411100301 | I38: D2001 | J38: 24 | K38: 24 | L38: Sales MQH cá nhân | M38: Sanyo Minh Long | N38: =VLOOKUP(Table1[[#This Row],[elevator_traction_machine]],'Product inf'!A:B,2,FALSE) -> SP015 | O38: Bê tông | P38: Tải khách | Q38: Ziehl-Abegg - Đức | R38: Sanotec DREAM control | S38: 380000000 | U38: 380000000 | V38: 394000000 | X38: 6000000 | Y38: 6000000 | Z38: 45392 | AA38: D200142024
A39: 45742 | B39: 1103/HĐ-2025 | C39: thửa 1088, tờ số 01, p. thạnh mỹ lợi, tp. thủ đức, tp. hcm | D39: TP Hồ Chí Minh | E39: =VLOOKUP(D39,'shipping inf'!B:D,2,FALSE) -> TP Hồ Chí Minh | F39: KH034 | G39: 150 | H39: 2511100301 | I39: D2001 | J39: 24 | K39: 24 | L39: Sales MQH cá nhân | M39: Sanyo Minh Long | N39: =VLOOKUP(Table1[[#This Row],[elevator_traction_machine]],'Product inf'!A:B,2,FALSE) -> SP001 | O39: Bê tông | P39: Tải khách | Q39: Belt - Nhật Bản | R39: Sanotec DREAM control | S39: 415000000 | U39: 415000000 | V39: 429000000 | X39: 10000000 | Y39: 6000000 | Z39: 45742 | AA39: D200132025
A40: 45504 | B40: 1104/HĐ-2024 | C40: 451/7 tô hiến thành, p.14, q.10, tp. hcm | D40: TP Hồ Chí Minh | E40: =VLOOKUP(D40,'shipping inf'!B:D,2,FALSE) -> TP Hồ Chí Minh | F40: KH035 | G40: 120 | H40: 2411100401 | I40: D2001 | J40: 24 | K40: 24 | L40: Sales MQH cá nhân | M40: Sanyo Minh Long | N40: =VLOOKUP(Table1[[#This Row],[elevator_traction_machine]],'Product inf'!A:B,2,FALSE) -> SP015 | O40: Bê tông | P40: Tải khách | Q40: Ziehl-Abegg - Đức | R40: Sanotec DREAM control | S40: 391000000 | U40: 391000000 | V40: 394000000 | X40: 25000000 | Y40: 6000000 | Z40: 45519 | AA40: D200172024
...

Sheet Appendix data
A1: Appendix_date | B1: appendix_sequence | C1: contract_ID | D1: customer_ID | E1: appendix_value_before_tax | F1: appendix_vat_amountuế GTGT | G1: appendix_value_after_tax | H1: appendix_type
A2: 45664 | B2: 1 | C2: 207/HĐ-2024 | D2: =VLOOKUP(Table2[[#This Row],[contract_ID]],'Contract data'!B:F,5,FALSE) -> KH208 | E2: 6000000 | G2: 6000000 | H2: Variation Appendix
A3: 45665 | B3: 1 | C3: 401/HĐ-2024 | D3: =VLOOKUP(Table2[[#This Row],[contract_ID]],'Contract data'!B:F,5,FALSE) -> KH254 | G3: 0 | H3: No-Cost Addendum
A4: 45670 | B4: 1 | C4: 1001/HĐ-2024 | D4: =VLOOKUP(Table2[[#This Row],[contract_ID]],'Contract data'!B:F,5,FALSE) -> KH001 | G4: 0 | H4: No-Cost Addendum
A5: 45669 | B5: 1 | C5: 1110/HĐ-2024 | D5: =VLOOKUP(Table2[[#This Row],[contract_ID]],'Contract data'!B:F,5,FALSE) -> KH045 | G5: 0 | H5: No-Cost Addendum
A6: 45670 | B6: 1 | C6: 1105/HĐ-2024 | D6: =VLOOKUP(Table2[[#This Row],[contract_ID]],'Contract data'!B:F,5,FALSE) -> KH037 | E6: -2000000 | G6: -2000000 | H6: Deduction Appendix
A7: 45661 | B7: 1 | C7: 1112/HĐ-2024 | D7: =VLOOKUP(Table2[[#This Row],[contract_ID]],'Contract data'!B:F,5,FALSE) -> KH047 | E7: -2000000 | G7: -2000000 | H7: Deduction Appendix
A8: 45673 | B8: 1 | C8: 517/HĐ-2024 | D8: =VLOOKUP(Table2[[#This Row],[contract_ID]],'Contract data'!B:F,5,FALSE) -> KH284 | G8: 0 | H8: No-Cost Addendum
A9: 45673 | B9: 1 | C9: 504/HĐ-2024 | D9: =VLOOKUP(Table2[[#This Row],[contract_ID]],'Contract data'!B:F,5,FALSE) -> KH268 | G9: 0 | H9: No-Cost Addendum
A10: 45677 | B10: 1 | C10: 613/HĐ-2024 | D10: =VLOOKUP(Table2[[#This Row],[contract_ID]],'Contract data'!B:F,5,FALSE) -> KH310 | E10: 2500000 | G10: 2500000 | H10: Variation Appendix
A11: 45677 | B11: 1 | C11: 125/HĐ-2024 | D11: =VLOOKUP(Table2[[#This Row],[contract_ID]],'Contract data'!B:F,5,FALSE) -> KH095 | E11: -1600000 | G11: -1600000 | H11: Deduction Appendix
A12: 45671 | B12: 1 | C12: 126/HĐ-2024 | D12: =VLOOKUP(Table2[[#This Row],[contract_ID]],'Contract data'!B:F,5,FALSE) -> KH097 | E12: 41000000 | G12: 41000000 | H12: Variation Appendix
A13: 45680 | B13: 1 | C13: 115/HĐ-2024 | D13: =VLOOKUP(Table2[[#This Row],[contract_ID]],'Contract data'!B:F,5,FALSE) -> KH056 | G13: 0 | H13: No-Cost Addendum
A14: 45694 | B14: 1 | C14: 134/HĐ-2024 | D14: =VLOOKUP(Table2[[#This Row],[contract_ID]],'Contract data'!B:F,5,FALSE) -> KH110 | G14: 0 | H14: No-Cost Addendum
A15: 45679 | B15: 1 | C15: 1202/HĐ-2024 | D15: =VLOOKUP(Table2[[#This Row],[contract_ID]],'Contract data'!B:F,5,FALSE) -> KH070 | E15: 3000000 | G15: 3000000 | H15: Variation Appendix
A16: 45688 | B16: 1 | C16: 601/HĐ-2025 | D16: =VLOOKUP(Table2[[#This Row],[contract_ID]],'Contract data'!B:F,5,FALSE) -> KH290 | G16: 0 | H16: No-Cost Addendum
A17: 45698 | B17: 1 | C17: 213/HĐ-2024 | D17: =VLOOKUP(Table2[[#This Row],[contract_ID]],'Contract data'!B:F,5,FALSE) -> KH219 | G17: 0 | H17: No-Cost Addendum
A18: 45698 | B18: 2 | C18: 134/HĐ-2024 | D18: =VLOOKUP(Table2[[#This Row],[contract_ID]],'Contract data'!B:F,5,FALSE) -> KH110 | G18: 0 | H18: No-Cost Addendum
A19: 45701 | B19: 1 | C19: 520/HĐ-2024 | D19: =VLOOKUP(Table2[[#This Row],[contract_ID]],'Contract data'!B:F,5,FALSE) -> KH287 | G19: 0 | H19: No-Cost Addendum
A20: 45698 | B20: 1 | C20: 141/HĐ-2024 | D20: =VLOOKUP(Table2[[#This Row],[contract_ID]],'Contract data'!B:F,5,FALSE) -> KH121 | E20: 40000000 | G20: 40000000 | H20: Variation Appendix
A21: 45703 | B21: 1 | C21: 1206/HĐ-2024 | D21: =VLOOKUP(Table2[[#This Row],[contract_ID]],'Contract data'!B:F,5,FALSE) -> KH076 | G21: 0 | H21: No-Cost Addendum
A22: 45705 | B22: 1 | C22: 814/HĐ-2024 | D22: =VLOOKUP(Table2[[#This Row],[contract_ID]],'Contract data'!B:F,5,FALSE) -> KH354 | E22: 12000000 | G22: 12000000 | H22: Variation Appendix
A23: 45706 | B23: 1 | C23: 819/HĐ-2024 | D23: =VLOOKUP(Table2[[#This Row],[contract_ID]],'Contract data'!B:F,5,FALSE) -> KH364 | G23: 0 | H23: No-Cost Addendum
A24: 45713 | B24: 3 | C24: 134/HĐ-2024 | D24: =VLOOKUP(Table2[[#This Row],[contract_ID]],'Contract data'!B:F,5,FALSE) -> KH110 | E24: 25500000 | G24: 25500000 | H24: Variation Appendix
A25: 45714 | B25: 1 | C25: 139/HĐ-2024 | D25: =VLOOKUP(Table2[[#This Row],[contract_ID]],'Contract data'!B:F,5,FALSE) -> KH011 | G25: 0 | H25: No-Cost Addendum
A26: 45714 | B26: 1 | C26: 140/HĐ-2024 | D26: =VLOOKUP(Table2[[#This Row],[contract_ID]],'Contract data'!B:F,5,FALSE) -> KH119 | G26: 0 | H26: No-Cost Addendum
A27: 45715 | B27: 2 | C27: 1202/HĐ-2024 | D27: =VLOOKUP(Table2[[#This Row],[contract_ID]],'Contract data'!B:F,5,FALSE) -> KH070 | E27: 20600000 | G27: 20600000 | H27: Variation Appendix
A28: 45719 | B28: 2 | C28: 141/HĐ-2024 | D28: =VLOOKUP(Table2[[#This Row],[contract_ID]],'Contract data'!B:F,5,FALSE) -> KH121 | E28: 38500000 | G28: 38500000 | H28: Variation Appendix
A29: 45715 | B29: 1 | C29: 1201/HĐ-2025 | D29: =VLOOKUP(Table2[[#This Row],[contract_ID]],'Contract data'!B:F,5,FALSE) -> KH068 | G29: 0 | H29: No-Cost Addendum
A30: 45715 | B30: 1 | C30: 135/HĐ-2024 | D30: =VLOOKUP(Table2[[#This Row],[contract_ID]],'Contract data'!B:F,5,FALSE) -> KH112 | E30: 35500000 | G30: 35500000 | H30: Variation Appendix
A31: 45714 | B31: 1 | C31: 309/HĐ-2024 | D31: =VLOOKUP(Table2[[#This Row],[contract_ID]],'Contract data'!B:F,5,FALSE) -> KH240 | E31: 61500000 | G31: 61500000 | H31: Variation Appendix
A32: 45715 | B32: 2 | C32: 309/HĐ-2024 | D32: =VLOOKUP(Table2[[#This Row],[contract_ID]],'Contract data'!B:F,5,FALSE) -> KH240 | G32: 0 | H32: No-Cost Addendum
A33: 45724 | B33: 2 | C33: 1206/HĐ-2024 | D33: =VLOOKUP(Table2[[#This Row],[contract_ID]],'Contract data'!B:F,5,FALSE) -> KH076 | E33: 800000 | G33: 800000 | H33: Variation Appendix
A34: 45721 | B34: 4 | C34: 134/HĐ-2024 | D34: =VLOOKUP(Table2[[#This Row],[contract_ID]],'Contract data'!B:F,5,FALSE) -> KH110 | G34: 0 | H34: No-Cost Addendum
A35: 45708 | B35: 1 | C35: 122/HĐ-2024 | D35: =VLOOKUP(Table2[[#This Row],[contract_ID]],'Contract data'!B:F,5,FALSE) -> KH090 | E35: 33000000 | G35: 33000000 | H35: Variation Appendix
A36: 45726 | B36: 1 | C36: 1504/HĐ-2025 | D36: =VLOOKUP(Table2[[#This Row],[contract_ID]],'Contract data'!B:F,5,FALSE) -> KH140 | E36: -1200000 | G36: -1200000 | H36: Deduction Appendix
A37: 45715 | B37: 3 | C37: 1202/HĐ-2024 | D37: =VLOOKUP(Table2[[#This Row],[contract_ID]],'Contract data'!B:F,5,FALSE) -> KH070 | G37: 0 | H37: No-Cost Addendum
A38: 45728 | B38: 1 | C38: 302/HĐ-2025 | D38: =VLOOKUP(Table2[[#This Row],[contract_ID]],'Contract data'!B:F,5,FALSE) -> KH230 | G38: 0 | H38: No-Cost Addendum
A39: 45730 | B39: 1 | C39: 204/HĐ-2024 | D39: =VLOOKUP(Table2[[#This Row],[contract_ID]],'Contract data'!B:F,5,FALSE) -> KH202 | E39: 10000000 | G39: 10000000 | H39: Variation Appendix
A40: 45734 | B40: 4 | C40: 1202/HĐ-2024 | D40: =VLOOKUP(Table2[[#This Row],[contract_ID]],'Contract data'!B:F,5,FALSE) -> KH070 | E40: 6000000 | G40: 6000000 | H40: Variation Appendix
...

Sheet Customer
A1: customer_name | B1: customer_ID | C1: customer_type | D1: customer_phone
A2: phạm văn sơn | B2: KH001 | C2: private | D2: 913901630
A3: trần dương phương hùng | B3: KH002 | C3: private | D3: 909092650
A4: ông nguyễn khắc giang | B4: KH003 | C4: private | D4: 938836567
A5: huỳnh thị xuân | B5: KH004 | C5: private | D5: 909206494
A6: công ty cổ phần thực phẩm cát hải | B6: KH005 | C6: company | D6: 836204897
A7: ông nguyễn văn nhẫn | B7: KH006 | C7: private | D7: 913906520
A8: nguyễn thị bích ngọc | B8: KH007 | C8: private
A9: công ty tnhh đầu tư phát triển khách sạn hoàng phát | B9: KH008 | C9: company | D9: 968726091
A10: trần mỹ ngọc | B10: KH009 | C10: private | D10: 907031989
A11: ông dương mạnh trung | B11: KH010 | C11: private | D11: 909769980
A12: trần đức thọ | B12: KH011 | C12: private | D12: 965824456
A13: công ty tnhh thương mại - xây dựng lê thành | B13: KH012 | C13: company | D13: 839803129
A14: trần thị bình | B14: KH013 | C14: private | D14: 918319710
A15: đinh hữu nhân | B15: KH014 | C15: private | D15: 908246467
A16: ông tăng viết hùng | B16: KH015 | C16: private | D16: 949371199
A17: tạ anh tuấn | B17: KH016 | C17: private | D17: 908351120
A18: huỳnh thành chung | B18: KH017 | C18: private | D18: 913880000
A19: bà nguyễn tô vân | B19: KH018 | C19: private | D19: 975446462
A20: công ty cp xd nghĩa trung | B20: KH019 | C20: company
A21: nguyễn thanh sơn | B21: KH020 | C21: private | D21: 936188788
A22: bà biện kim loan | B22: KH021 | C22: private | D22: 939695522
A23: trương anh minh | B23: KH022 | C23: private | D23: 971567028
A24: trần vĩnh phúc | B24: KH023 | C24: private | D24: 932009799
A25: ông vũ bá ổn | B25: KH024 | C25: private | D25: 913235546
A26: công ty tnhh căn hộ mt thảo điền | B26: KH025 | C26: company | D26: 967138868
A27: lê chuyển | B27: KH026 | C27: private | D27: 985923471
A28: ông bùi lê khiêm | B28: KH027 | C28: private | D28: 901125423
A29: đặng minh sơn | B29: KH028 | C29: private | D29: 907298678
A30: trần thái hưng | B30: KH029 | C30: private | D30: 913780859
A31: bà ngô thị lâm | B31: KH030 | C31: private | D31: 913194045
A32: lê nguyễn ngọc vũ | B32: KH031 | C32: private | D32: 904798968
... A44: công ty cổ phần tư vấn thiết kế và đầu tư xây dựng đất việt | B44: KH043 | C44: company | D44: 422111999
A45: công ty tnhh nguồn á châu | B45: KH044 | C45: company
A46: huỳnh minh tuyến | B46: KH045 | C46: private | D46: 908774006
A47: trần quang hiển | B47: KH046 | C47: private | D47: 918603799
A48: nguyễn văn thống | B48: KH047 | C48: private | D48: 988818083
A49: nguyễn hữu trọng | B49: KH048 | C49: private | D49: 966805078
A50: võ tuấn minh | B50: KH049 | C50: private | D50: 987085612
A51: lâm thị mỹ phượng | B51: KH050 | C51: private | D51: 918271527
...

Sheet shipping inf
A1: region | B1: province_old | C1: province_new | D1: area_type | E1: shipping_cost
A2: Miền Bắc | B2: Hà Nội | C2: Hà Nội | D2: suburban | E2: 30000000
A3: Miền Bắc | B3: Cao Bằng | C3: Cao Bằng | D3: suburban | E3: 30000000
A4: Miền Bắc | B4: Điện Biên | C4: Điện Biên | D4: suburban | E4: 30000000
A5: Miền Bắc | B5: Lai Châu | C5: Lai Châu | D5: suburban | E5: 30000000
A6: Miền Bắc | B6: Sơn La | C6: Sơn La | D6: suburban | E6: 30000000
A7: Miền Bắc | B7: Lạng Sơn | C7: Lạng Sơn | D7: suburban | E7: 30000000
A8: Miền Bắc | B8: Quảng Ninh | C8: Quảng Ninh | D8: suburban | E8: 30000000
A9: Miền Bắc | B9: Thanh Hóa | C9: Thanh Hóa | D9: suburban | E9: 30000000
A10: Miền Bắc | B10: Nghệ An | C10: Nghệ An | D10: suburban | E10: 30000000
A11: Miền Bắc | B11: Hà Giang | C11: Tuyên Quang | D11: suburban | E11: 30000000
A12: Miền Bắc | B12: Tuyên Quang | C12: Tuyên Quang | D12: suburban | E12: 30000000
A13: Miền Bắc | B13: Lào Cai | C13: Lào Cai | D13: suburban | E13: 30000000
... A64: Miền Trung | B64: Phú Yên | C64: Đắk Lắk | D64: suburban | E64: 25000000

Sheet Product inf
A1: product_name | B1: product_ID | C1: product_origin
A2: Belt - Nhật Bản | B2: SP001 | C2: Nhật Bản
A3: Belt - Trung Quốc | B3: SP002 | C3: Trung Quốc
A4: Fuji Korea - Hàn Quốc | B4: SP003 | C4: Hàn Quốc
A5: Motor Mitsubishi - Nhật Bản | B5: SP004 | C5: Nhật Bản
A6: Sanotec - Eco Trung Quốc | B6: SP005 | C6: Trung Quốc
A7: Sanotec - Nhật Bản | B7: SP006 | C7: Nhật Bản
A8: Sanotec - Nidec | B8: SP007 | C8: Thụy Sỹ
A9: Sanotec - Trung Quốc | B9: SP008 | C9: Trung Quốc
A10: Sanotec Eco - Nhật Bản | B10: SP009 | C10: Nhật Bản
A11: Sanotec Eco - Trung Quốc | B11: SP010 | C11: Trung Quốc
A12: Sanotec HP - Trung Quốc | B12: SP011 | C12: Trung Quốc
... A16: Ziehl-Abegg - Đức | B16: SP015 | C16: Đức

Sheet Saleman inf
A1: Saleman_name | B1: posision | C1: saleman_ID
A2: ĐỖ HỒNG VĂN | B2: Dept. 1 | C2: D1001
A3: TRƯƠNG TRỌNG THỊNH | B3: Dept. 1 | C3: D1002
A4: TRẦN ĐỨC THUẬN | B4: Dept. 1 | C4: D1003
A5: DƯƠNG MINH LÊ QUỲNH | B5: Dept. 1 | C5: D1004
A6: UNG TRIỆU THẮNG | B6: Dept. 2 | C6: D2001
A7: NGUYỄN HOÀNG MINH THÁI | B7: Dept. 2 | C7: D2002
A8: NGUYỄN DUY PHƯỚC | B8: Dept. 2 | C8: D2003
A9: PHẠM TẤN ĐỨC | B9: Dept. 2 | C9: D2004
A10: NGUYỄN THẾ ĐỨC DUY | B10: Dept. 2 | C10: D2005
A11: NGUYỄN BẢO HUY | B11: Dept. 2 | C11: D2006
A12: NGUYỄN ANH VŨ | B12: Dept. 2 | C12: D2007
... A22: TRẦN THANH LIÊM | B22: Dept. 4 | C22: D4001

Sheet Saleman_KPI
A1: Saleman_name | B1: saleman_ID | C1: Month | D1: Year | E1: import_staff | F1: KPI_units
A2: ĐỖ HỒNG VĂN | B2: D1001 | C2: 1 | D2: 2024 | E2: D100112024
A3: TRƯƠNG TRỌNG THỊNH | B3: D1002 | C3: 1 | D3: 2024 | E3: D100212024
A4: TRẦN ĐỨC THUẬN | B4: D1003 | C4: 1 | D4: 2024 | E4: D100312024 | F4: 2
A5: DƯƠNG MINH LÊ QUỲNH | B5: D1004 | C5: 1 | D5: 2024 | E5: D100412024
A6: UNG TRIỆU THẮNG | B6: D2001 | C6: 1 | D6: 2024 | E6: D200112024
A7: NGUYỄN HOÀNG MINH THÁI | B7: D2002 | C7: 1 | D7: 2024 | E7: D200212024
A8: NGUYỄN DUY PHƯỚC | B8: D2003 | C8: 1 | D8: 2024 | E8: D200312024
A9: PHẠM TẤN ĐỨC | B9: D2004 | C9: 1 | D9: 2024 | E9: D200412024
A10: NGUYỄN THẾ ĐỨC DUY | B10: D2005 | C10: 1 | D10: 2024 | E10: D200512024 | F10: 1
A11: NGUYỄN BẢO HUY | B11: D2006 | C11: 1 | D11: 2024 | E11: D200612024
A12: NGUYỄN ANH VŨ | B12: D2007 | C12: 1 | D12: 2024 | E12: D200712024
A13: NGUYỄN THANH TÙNG | B13: D2008 | C13: 1 | D13: 2024 | E13: D200812024
A14: NGUYỄN VĂN SƠN | B14: D2009 | C14: 1 | D14: 2024 | E14: D200912024
A15: VÕ KHÁNH DUY | B15: D2010 | C15: 1 | D15: 2024 | E15: D201012024
A16: TRẦN MINH TIẾN | B16: D2011 | C16: 1 | D16: 2024 | E16: D201112024
A17: DƯƠNG QUỐC KIÊN | B17: D2012 | C17: 1 | D17: 2024 | E17: D201212024
A18: TRẦN THẾ TRUNG | B18: D2013 | C18: 1 | D18: 2024 | E18: D201312024 | F18: 1
A19: VÒNG NGUYỄN NGỌC OANH | B19: D3001 | C19: 1 | D19: 2024 | E19: D300112024
A20: TRẦN MINH TIẾN B2B | B20: D3002 | C20: 1 | D20: 2024 | E20: D300212024
A21: LÂM TÂM HÙNG | B21: D3003 | C21: 1 | D21: 2024 | E21: D300312024
A22: TRẦN THANH LIÊM | B22: D4001 | C22: 1 | D22: 2024 | E22: D400112024 | F22: 2
A23: ĐỖ HỒNG VĂN | B23: D1001 | C23: 2 | D23: 2024 | E23: D100122024 | F23: 3
A24: TRƯƠNG TRỌNG THỊNH | B24: D1002 | C24: 2 | D24: 2024 | E24: D100222024
A25: TRẦN ĐỨC THUẬN | B25: D1003 | C25: 2 | D25: 2024 | E25: D100322024 | F25: 3
A26: DƯƠNG MINH LÊ QUỲNH | B26: D1004 | C26: 2 | D26: 2024 | E26: D100422024
A27: UNG TRIỆU THẮNG | B27: D2001 | C27: 2 | D27: 2024 | E27: D200122024
A28: NGUYỄN HOÀNG MINH THÁI | B28: D2002 | C28: 2 | D28: 2024 | E28: D200222024 | F28: 2
A29: NGUYỄN DUY PHƯỚC | B29: D2003 | C29: 2 | D29: 2024 | E29: D200322024
A30: PHẠM TẤN ĐỨC | B30: D2004 | C30: 2 | D30: 2024 | E30: D200422024
A31: NGUYỄN THẾ ĐỨC DUY | B31: D2005 | C31: 2 | D31: 2024 | E31: D200522024 | F31: 1
A32: NGUYỄN BẢO HUY | B32: D2006 | C32: 2 | D32: 2024 | E32: D200622024 | F32: 1
A33: NGUYỄN ANH VŨ | B33: D2007 | C33: 2 | D33: 2024 | E33: D200722024
A34: NGUYỄN THANH TÙNG | B34: D2008 | C34: 2 | D34: 2024 | E34: D200822024
A35: NGUYỄN VĂN SƠN | B35: D2009 | C35: 2 | D35: 2024 | E35: D200922024
A36: VÕ KHÁNH DUY | B36: D2010 | C36: 2 | D36: 2024 | E36: D201022024
A37: TRẦN MINH TIẾN | B37: D2011 | C37: 2 | D37: 2024 | E37: D201122024
A38: DƯƠNG QUỐC KIÊN | B38: D2012 | C38: 2 | D38: 2024 | E38: D201222024
A39: TRẦN THẾ TRUNG | B39: D2013 | C39: 2 | D39: 2024 | E39: D201322024
A40: VÒNG NGUYỄN NGỌC OANH | B40: D3001 | C40: 2 | D40: 2024 | E40: D300122024
...
